<?xml version="1.0"?>
<!-- created with Phobos 1.0.1 "Capricious Choutengan" -->
  <robot name="xarm">
 	<link name="world"/>

    <link name="base_link">
      <inertial>
        <origin xyz="0 0 0.01319212" rpy="0 0 0"/>
        <mass value="0.15"/>
        <inertia ixx="1368.19627286" ixy="0" ixz="0" iyy="1295.53672831" iyz="0" izz="0.0744866"/>
      </inertial>
      <visual name="base_columns">
        <origin xyz="0 0 0.00003818" rpy="0 0 0"/>
        <geometry>
          <mesh filename="neu_ro_arm/assets/meshes/base_columns.dae" scale="1.0 1.0 1.0"/>
        </geometry>
        <material name="blue"/>
      </visual>
      <visual name="base_lower_part">
        <origin xyz="0 0 0" rpy="0 0 0"/>
        <geometry>
          <mesh filename="neu_ro_arm/assets/meshes/base_lower_part.dae" scale="38.5 35.0 1.0"/>
        </geometry>
      </visual>
      <visual name="base_upper_part">
        <origin xyz="0 0 0.03953818" rpy="0 0 0"/>
        <geometry>
          <mesh filename="neu_ro_arm/assets/meshes/base_upper_part.dae" scale="28.5 28.5 0.75"/>
        </geometry>
      </visual>
      <collision name="base_001">
        <origin xyz="0 0 0" rpy="0 0 0"/>
        <geometry>
          <box size="0.15400229 0.1400 0.0020"/>
        </geometry>
      </collision>
      <collision name="hex-columns">
        <origin xyz="0 0 0.01703818" rpy="0 0 0"/>
        <geometry>
          <box size="0.07606218 0.0770 0.0320"/>
        </geometry>
      </collision>
      <collision name="hexplates">
        <origin xyz="0 0 0.03953818" rpy="0 0 0"/>
        <geometry>
          <cylinder radius="0.06164659" length="0.0130"/>
        </geometry>
      </collision>
    </link>

    <link name="swivel_link">
      <inertial>
        <origin xyz="0 -0.006 0.01046303" rpy="0 0 0"/>
        <mass value="0.15"/>
        <inertia ixx="0.95028073" ixy="-0.2352502" ixz="-0.42875996" iyy="0.7482846" iyz="0.06185786" izz="0.9494582"/>
      </inertial>
      <visual name="shoulder_servo">
        <origin xyz="0 -0.00100 0.02419454" rpy="0 0 -1.5708"/>
        <geometry>
          <mesh filename="neu_ro_arm/assets/meshes/shoulder_servo.dae" scale="20.0 20.0 10.0"/>
        </geometry>
        <material name="blue"/>
      </visual>
      <visual name="swivel">
        <origin xyz="0 0 0" rpy="0 0 0"/>
        <geometry>
          <mesh filename="neu_ro_arm/assets/meshes/swivel.dae" scale="1.0 1.0 1.0"/>
        </geometry>
      </visual>
      <visual name="swivel_servo_holder">
        <origin xyz="0 -0.008 0.00719454" rpy="0 0 0"/>
        <geometry>
          <mesh filename="neu_ro_arm/assets/meshes/swivel_servo_holder.dae" scale="1.0 1.0 1.0"/>
        </geometry>
      </visual>
      <collision name="swivel-servo-holder">
        <origin xyz="0 -0.0080 0.02031954" rpy="0 0 0"/>
        <geometry>
          <box size="0.04350001 0.0400 0.02775"/>
        </geometry>
      </collision>
    </link>

    <link name="upperarm_link">
      <inertial>
        <origin xyz="-0.02716456 0 0" rpy="0 0 0"/>
        <mass value="0.1"/>
        <inertia ixx="0.0002" ixy="0" ixz="0" iyy="0.0002" iyz="0" izz="0.0002"/>
      </inertial>
      <visual name="upperarm_lower">
        <origin xyz="0 0 0" rpy="0 1.5708 0"/>
        <geometry>
          <mesh filename="neu_ro_arm/assets/meshes/upperarm_lower.dae" scale="1.0 1.0 1.0"/>
        </geometry>
        <material name="blue"/>
      </visual>
      <visual name="upperarm_plastic_part">
        <origin xyz="-0.05432911 0 0" rpy="-1.5708 1.5708 0"/>
        <geometry>
          <mesh filename="neu_ro_arm/assets/meshes/upperarm_plastic_part.dae" scale="1.0 1.0 1.0"/>
        </geometry>
      </visual>
      <visual name="upperarm_small_metal_part">
        <origin xyz="-0.09882912 -0.0000231 0" rpy="1.5708 0 -1.5708"/>
        <geometry>
          <mesh filename="neu_ro_arm/assets/meshes/upperarm_small_metal_part.dae" scale="1.0 1.0 1.0"/>
        </geometry>
      </visual>
      <collision name="upperarm">
        <origin xyz="-0.05 0 0" rpy="0 1.5708 0"/>
        <geometry>
          <box size="0.05600002 0.0320 0.11"/>
        </geometry>
      </collision>
    </link>

    <link name="forearm_link">
      <inertial>
        <origin xyz="0 0.04168909 0" rpy="0 0 0"/>
        <mass value="0.04"/>
        <inertia ixx="0.0002" ixy="0.0002" ixz="0" iyy="0.0002" iyz="0" izz="0.0002"/>
      </inertial>
      <visual name="forearm_lower_servo">
        <origin xyz="0 0 0" rpy="0 0 0"/>
        <geometry>
          <mesh filename="neu_ro_arm/assets/meshes/forearm_lower_servo.dae" scale="11.5 22.00001 13.5"/>
        </geometry>
        <material name="blue"/>
      </visual>
      <visual name="forearm_metal_part">
        <origin xyz="0 0.03608548 0" rpy="-1.5708 0 -3.14159"/>
        <geometry>
          <mesh filename="neu_ro_arm/assets/meshes/forearm_metal_part.dae" scale="1.0 1.0 1.0"/>
        </geometry>
      </visual>
      <visual name="forearm_plastic_part">
        <origin xyz="0 0.04733547 0" rpy="0 -1.5708 0"/>
        <geometry>
          <mesh filename="neu_ro_arm/assets/meshes/forearm_plastic_part.dae" scale="1.0 1.0 1.0"/>
        </geometry>
      </visual>
      <visual name="wrist_servo">
        <origin xyz="0 0.08333548 0" rpy="3.14159 0 0"/>
        <geometry>
          <mesh filename="neu_ro_arm/assets/meshes/wrist_servo.dae" scale="11.5 22.00001 13.5"/>
        </geometry>
      </visual>
      <collision name="forearm">
        <origin xyz="0 0.05 0" rpy="0 0 0"/>
        <geometry>
          <box size="0.0230 0.09 0.03512"/>
        </geometry>
      </collision>
    </link>

    <link name="wrist_link">
      <inertial>
        <origin xyz="-0.00566908 -0.01834498 0" rpy="0 0 0"/>
        <mass value="0.02"/>
        <inertia ixx="0.1629017" ixy="0.00069143" ixz="-0.00103996" iyy="0.42251036" iyz="-0.30887766" izz="0.59882158"/>
      </inertial>
      <visual name="wrist_metal_part">
        <origin xyz="0 0 0" rpy="-1.5708 0 0"/>
        <geometry>
          <mesh filename="neu_ro_arm/assets/meshes/wrist_metal_part.dae" scale="1.0 1.0 1.0"/>
        </geometry>
        <material name="blue"/>
      </visual>
      <visual name="wrist_rotation_servo">
        <origin xyz="-0.01133817 -0.03669003 0" rpy="1.5708 -1.5708 0"/>
        <geometry>
          <mesh filename="neu_ro_arm/assets/meshes/wrist_rotation_servo.dae" scale="11.5 22.0 13.5"/>
        </geometry>
      </visual>
      <collision name="wrist">
        <origin xyz="-0.0101 -0.01937499 0" rpy="-1.5708 0 0"/>
        <geometry>
          <box size="0.0470 0.0405 0.06475"/>
        </geometry>
      </collision>
    </link>

    <link name="hand_link">
      <inertial>
        <origin xyz="0.00133091 0.01253 0" rpy="0 0 0"/>
        <mass value="0.02"/>
        <inertia ixx="18.15680311" ixy="0.00001878" ixz="-0.0711049" iyy="0.05046617" iyz="-0.02529274" izz="0.05071621"/>
      </inertial>
      <visual name="hand_part">
        <origin xyz="0 0 0" rpy="-1.5708 -3.14159 0"/>
        <geometry>
          <mesh filename="neu_ro_arm/assets/meshes/hand_part.dae" scale="28.5 12.0 1.5"/>
        </geometry>
        <material name="black"/>
      </visual>
      <visual name="hand_servo">
        <origin xyz="0.00266182 0.02506001 2e-08" rpy="1.5708 1.5708 0"/>
        <geometry>
          <mesh filename="neu_ro_arm/assets/meshes/hand_servo.dae" scale="11.5 22.0 13.5"/>
        </geometry>
      </visual>
      <collision name="LX-15D.001">
        <origin xyz="0.00266182 0.002303001 0" rpy="1.57061 1.5708 0"/>
        <geometry>
          <box size="0.0230 0.0440 0.03106"/>
        </geometry>
      </collision>
      <collision name="hand">
        <origin xyz="0.00348131 0 -0.001" rpy="1.55239 -3.14159 0"/>
        <geometry>
          <cylinder radius="0.03339804" length="0.00451872"/>
        </geometry>
      </collision>
    </link>

    <link name="left_finger_bar_link">
      <inertial>
        <origin xyz="0 0 0" rpy="0 0 0"/>
        <mass value="0.01"/>
        <inertia ixx="0.0001" ixy="0" ixz="0" iyy="2e-08" iyz="0" izz="2e-08"/>
      </inertial>
      <visual name="left_finger_bar">
        <origin xyz="0 0 0" rpy="0 0 0"/>
        <geometry>
          <mesh filename="neu_ro_arm/assets/meshes/left_finger_bar.dae" scale="10.0 1.0 1.0"/>
        </geometry>
        <material name="black"/>
      </visual>
      <collision name="left-finger-bar">
        <origin xyz="0.015 0.0015 0.0015" rpy="0 0 0"/>
        <geometry>
          <box size="0.018 0.003 0.003"/>
        </geometry>
      </collision>
    </link>

    <link name="left_finger_base_link">
      <inertial>
        <origin xyz="0 0 0" rpy="0 0 0"/>
        <mass value="0.01"/>
        <inertia ixx="0.0001" ixy="0" ixz="0" iyy="0.0001" iyz="0" izz="0.0001"/>
      </inertial>
      <visual name="left_finger_base">
        <origin xyz="0 0 0" rpy="0 0 0"/>
        <geometry>
          <mesh filename="neu_ro_arm/assets/meshes/right_finger_base.dae" scale="1.0 1.0 1.0"/>
        </geometry>
        <material name="black"/>
      </visual>
      <collision name="left-finger-lower">
        <origin xyz="0 0.011125001 0" rpy="0 0 0"/>
        <geometry>
          <box size="0.01 0.0375 0.003"/>
        </geometry>
      </collision>
    </link>

    <link name="left_finger_tip_link">
      <inertial>
        <origin xyz="0 0 0" rpy="0 0 0"/>
        <mass value="0.01"/>
        <inertia ixx="0.0001" ixy="0" ixz="0" iyy="0.0001" iyz="0" izz="0.0001"/>
      </inertial>
      <visual name="left_finger_tip">
        <origin xyz="-3e-08 4e-08 0" rpy="0 0 0"/>
        <geometry>
          <mesh filename="neu_ro_arm/assets/meshes/left_finger_tip.dae" scale="1.0 1.0 1.0"/>
        </geometry>
        <material name="black"/>
      </visual>
      <collision name="left-finger-upper">
        <origin xyz="-0.02841921 0.00624356 0.00303819" rpy="0 0 0"/>
        <geometry>
          <mesh filename="neu_ro_arm/assets/meshes/Circle.002.dae" scale="1.0 1.0 1.0"/>
        </geometry>
      </collision>
    </link>

    <link name="right_finger_bar_link">
      <inertial>
        <origin xyz="0 0 0" rpy="0 0 0"/>
        <mass value="0.01"/>
        <inertia ixx="0.0001" ixy="0" ixz="0" iyy="0.0001" iyz="0" izz="0.0001"/>
      </inertial>
      <visual name="right_finger_bar">
        <origin xyz="0 0 0" rpy="0 0 0"/>
        <geometry>
          <mesh filename="neu_ro_arm/assets/meshes/right_finger_bar.dae" scale="10.0 1.0 1.0"/>
        </geometry>
        <material name="black"/>
      </visual>
      <collision name="right-finger-bar">
        <origin xyz="-0.015 0.0015 0.0015" rpy="0 0 0"/>
        <geometry>
          <box size="0.018 0.003 0.003"/>
        </geometry>
      </collision>
    </link>

    <link name="right_finger_base_link">
      <inertial>
        <origin xyz="0 0 0" rpy="0 0 0"/>
        <mass value="0.01"/>
        <inertia ixx="0.0001" ixy="0" ixz="0" iyy="0.0001" iyz="0" izz="0.0001"/>
      </inertial>
      <visual name="right_finger_base">
        <origin xyz="0 0 0" rpy="0 0 0"/>
        <geometry>
          <mesh filename="neu_ro_arm/assets/meshes/right_finger_base.dae" scale="1.0 1.0 1.0"/>
        </geometry>
        <material name="black"/>
      </visual>
      <collision name="right-finger-lower">
        <origin xyz="0 0.011125001 0" rpy="0 0 0"/>
        <geometry>
          <box size="0.01 0.0375 0.003"/>
        </geometry>
      </collision>
    </link>

    <link name="right_finger_tip_link">
      <inertial>
        <origin xyz="0 0 0" rpy="0 0 0"/>
        <mass value="0.01"/>
        <inertia ixx="0.0001" ixy="0" ixz="0" iyy="0.0001" iyz="0" izz="0.0001"/>
      </inertial>
      <visual name="right_finger_tip">
        <origin xyz="0 1e-05 0" rpy="0 -3.14159 -0.88718"/>
        <geometry>
          <mesh filename="neu_ro_arm/assets/meshes/right_finger_tip.dae" scale="1.0 1.0 1.0"/>
        </geometry>
        <material name="black"/>
      </visual>
      <collision name="right-finger-upper">
        <origin xyz="0.02279521 -0.01810865 -0.00294544" rpy="0 -3.14159 -0.88718"/>
        <geometry>
          <mesh filename="neu_ro_arm/assets/meshes/Circle.003.dae" scale="1.0 1.0 1.0"/>
        </geometry>
      </collision>
    </link>

    <link name="virtual_grasp_link">
        <visual>
              <origin rpy="0 0 0.0" xyz="0 0.0 0.0"/>
              <geometry>
                <sphere radius="0.003"/>
              </geometry>
              <material name="red">
                <color rgba="0.8 0.2 0.2 0.5"/>
              </material>
        </visual>
        <inertial>
            <mass value="0.001"/>
            <inertia ixx="0.00001" ixy="0" ixz="0" iyy="0.00001" iyz="0" izz="0.00001"/>
        </inertial>
    </link>

    <joint name="world_joint" type="fixed">
        <parent link="world"/>
        <child link="base_link"/>
		<origin rpy="0.0 0.0 0.0" xyz="0.0 0.0 0.012"/>
    </joint>

    <joint name="base_joint" type="revolute">
      <origin xyz="0 0 0.03953818" rpy="0 0 1.5708"/>
      <parent link="base_link"/>
      <child link="swivel_link"/>
      <axis xyz="0 0 1.0"/>
      <limit lower="-2.0" upper="2.0" effort="0" velocity="2.0"/>
    </joint>

    <joint name="shoulder_joint" type="revolute">
      <origin xyz="0 0 0.024195" rpy="0 1.5708 0"/>
      <parent link="swivel_link"/>
      <child link="upperarm_link"/>
      <axis xyz="0 0 1.0"/>
      <limit lower="-1.58" upper="1.58" effort="0" velocity="2.0"/>
    </joint>

    <joint name="elbow_joint" type="revolute">
      <origin xyz="-0.09883501 0 0" rpy="0 0 1.5708"/>
      <parent link="upperarm_link"/>
      <child link="forearm_link"/>
      <axis xyz="0 0 1.0"/>
      <limit lower="-2.0" upper="2.0" effort="0" velocity="2.0"/>
    </joint>

    <joint name="wrist_joint" type="revolute">
      <origin xyz="0 0.09468611 0" rpy="0 0 3.14159"/>
      <parent link="forearm_link"/>
      <child link="wrist_link"/>
      <axis xyz="0 0 1.0"/>
      <limit lower="-2.0" upper="2.0" effort="0" velocity="2.0"/>
    </joint>

    <joint name="wrist_rotation_joint" type="revolute">
      <origin xyz="0 -0.08378503 0" rpy="1.5708 -1.5708 0"/>
      <parent link="wrist_link"/>
      <child link="hand_link"/>
      <axis xyz="0 0 1.0"/>
      <limit lower="-2.0" upper="2.0" effort="0" velocity="2.0"/>
    </joint>

    <joint name="left_finger_linkage_joint" type="revolute">
      <origin xyz="0.0045 -0.00852974 0.01950001" rpy="1.5708 -1.5708 0"/>
      <parent link="hand_link"/>
      <child link="left_finger_bar_link"/>
      <axis xyz="0 0 -1.0"/>
      <limit lower="0.0" upper="1.5" effort="0" velocity="2.0"/>
    </joint>

    <joint name="left_knuckle_joint" type="revolute">
        <origin xyz="0.014 -0.006 0" rpy="1.5708 0 0"/>
      <parent link="hand_link"/>
      <child link="left_finger_base_link"/>
      <axis xyz="0 0 -1.0"/>
      <limit lower="0.05" upper="1.38" effort="0" velocity="2.0"/>
    </joint>

    <joint name="left_finger_joint" type="revolute">
      <origin xyz="0.00002379 0.03001281 -0.0075" rpy="0 0 0.44359"/>
      <parent link="left_finger_base_link"/>
      <child link="left_finger_tip_link"/>
      <axis xyz="0 0 -1.0"/>
      <limit lower="-2.0" upper="2.0" velocity="2.0"/>
    </joint>

    <joint name="right_finger_linkage_joint" type="revolute">
      <origin xyz="-0.0045 -0.00852974 0.01950001" rpy="1.5708 1.5708 0"/>
      <parent link="hand_link"/>
      <child link="right_finger_bar_link"/>
      <axis xyz="0 0 1.0"/>
      <limit lower="0.0" upper="1.5" effort="0" velocity="2.0"/>
    </joint>

    <joint name="right_knuckle_joint" type="revolute">
      <origin xyz="-0.0140 -0.006 0" rpy="1.5708 0 0"/>
      <parent link="hand_link"/>
      <child link="right_finger_base_link"/>
      <axis xyz="0 0 1.0"/>
      <limit lower="0.05" upper="1.38" effort="0" velocity="2.0"/>
    </joint>

    <joint name="right_finger_joint" type="revolute">
      <origin xyz="-0.00002379 0.03001281 -0.0015" rpy="0 0 2.01439"/>
      <parent link="right_finger_base_link"/>
      <child link="right_finger_tip_link"/>
      <axis xyz="0 0 1.0"/>
      <limit lower="-2.0" upper="2.0" effort="0" velocity="2.0"/>
    </joint>

    <joint name="virtual_grasp_joint" type="fixed">
        <parent link="hand_link"/>
        <child link="virtual_grasp_link"/>
        <origin rpy="0.0 0.0 0.0" xyz="0.0 0.0 0.076"/>
    </joint>

    <material name="black">
      <color rgba="0.2 0.2 0.2 1.0"/>
    </material>

    <material name="blue">
      <!--<color rgba="0.1216 0.6236 0.8784 1.0"/>-->
      <color rgba="0.5 0.5 0.5 1.0"/>
    </material>

  </robot>
