<?xml version="1.0"?>
<!-- created with Phobos 1.0.1 "Capricious Choutengan" -->
  <robot name="xarm">
 	<link name="world"/>

    <link name="base_link">
      <inertial>
        <origin xyz="0 0 0.01319212" rpy="0 0 0"/>
        <mass value="0.15"/>
        <inertia ixx="0.001" ixy="0" ixz="0" iyy="0.001" iyz="0" izz="0.001"/>
      </inertial>
      <visual name="base">
        <origin xyz="0 0 0" rpy="0 0 0"/>
        <geometry>
          <mesh filename="nuro_arm/assets/meshes/base.stl" scale="0.001 0.001 0.001"/>
        </geometry>
        <material name="blue"/>
      </visual>
      <visual name="motor-controller">
        <origin xyz="-0.04 0 0.012" rpy="0 0 0"/>
        <geometry>
          <box size="0.05 0.075 0.003"/>
        </geometry>
        <material name="blue"/>
      </visual>
      <collision name="base_001">
        <origin xyz="0 0 0" rpy="0 0 0"/>
        <geometry>
          <box size="0.15400229 0.1400 0.0020"/>
        </geometry>
      </collision>
      <collision name="hex-columns">
        <origin xyz="0 0 0.01703818" rpy="0 0 0"/>
        <geometry>
          <box size="0.07606218 0.0770 0.0320"/>
        </geometry>
      </collision>
      <collision name="hexplates">
        <origin xyz="0 0 0.03953818" rpy="0 0 0"/>
        <geometry>
          <cylinder radius="0.06164659" length="0.0130"/>
        </geometry>
      </collision>
    </link>

    <link name="swivel_link">
      <inertial>
        <origin xyz="0 0.00 0.0" rpy="0 0 0"/>
        <mass value="0.15"/>
        <inertia ixx="0.001" ixy="0" ixz="0" iyy="0.001" iyz="0" izz="0.001"/>
      </inertial>
      <visual name="swivel">
        <origin xyz="0 0 0" rpy="0 0 3.14159"/>
        <geometry>
          <mesh filename="nuro_arm/assets/meshes/swivel.stl" scale="0.001 0.001 0.001"/>
        </geometry>
        <material name="blue"/>
      </visual>
      <collision name="swivel-servo-holder">
        <origin xyz="0 -0.0080 0.02031954" rpy="0 0 0"/>
        <geometry>
          <box size="0.04350001 0.0400 0.02775"/>
        </geometry>
      </collision>
    </link>

    <link name="upperarm_link">
      <inertial>
        <origin xyz="0 0 0" rpy="0 0 0"/>
        <mass value="0.1"/>
        <inertia ixx="0.0002" ixy="0" ixz="0" iyy="0.0002" iyz="0" izz="0.0002"/>
      </inertial>
      <visual name="upperarm_lower">
        <origin xyz="0 0 0" rpy="0 0 0"/>
        <geometry>
          <mesh filename="nuro_arm/assets/meshes/upperarm.stl" scale="0.001 0.001 0.001"/>
        </geometry>
        <material name="blue"/>
      </visual>
      <collision name="upperarm">
        <origin xyz="0.0 0 0.05" rpy="0 0 0"/>
        <geometry>
          <box size="0.032 0.056 0.11"/>
        </geometry>
      </collision>
    </link>

    <link name="forearm_link">
      <inertial>
        <origin xyz="0 0.0 0" rpy="0 0 0"/>
        <mass value="0.04"/>
        <inertia ixx="0.0001" ixy="0" ixz="0" iyy="0.0001" iyz="0" izz="0.0001"/>
      </inertial>
      <visual name="forearm">
        <origin xyz="0 0 0" rpy="0 0 0"/>
        <geometry>
          <mesh filename="nuro_arm/assets/meshes/forearm.stl" scale="0.001 0.001 0.001"/>
        </geometry>
        <material name="blue"/>
      </visual>
      <collision name="forearm">
        <origin xyz="0 0 0.05" rpy="0 0 0"/>
        <geometry>
          <box size="0.023 0.035 0.09"/>
        </geometry>
      </collision>
    </link>

    <link name="wrist_link">
      <inertial>
        <origin xyz="0.0 0.0 0" rpy="0 0 0"/>
        <mass value="0.02"/>
        <inertia ixx="0.0001" ixy="0" ixz="0" iyy="0.0001" iyz="0" izz="0.0001"/>
      </inertial>
      <visual name="wrist_metal_part">
        <origin xyz="0 0 0" rpy="0 0 3.14159"/>
        <geometry>
          <mesh filename="nuro_arm/assets/meshes/wrist.stl" scale="0.001 0.001 0.001"/>
        </geometry>
        <material name="blue"/>
      </visual>
      <collision name="wrist">
        <origin xyz="-0.0101 0.0 0.02" rpy="0 0 3.14159"/>
        <geometry>
          <box size="0.045 0.047 0.06475"/>
        </geometry>
      </collision>
    </link>

    <link name="hand_link">
      <inertial>
        <origin xyz="0.0 0.0 0" rpy="0 0 0"/>
        <mass value="0.02"/>
        <inertia ixx="0.0001" ixy="0" ixz="0" iyy="0.0001" iyz="0" izz="0.0001"/>
      </inertial>
      <visual name="hand">
        <origin xyz="0 0 0" rpy="0 0 3.14159"/>
        <geometry>
          <mesh filename="nuro_arm/assets/meshes/hand.stl" scale="0.001 0.001 0.001"/>
        </geometry>
        <material name="black"/>
      </visual>
      <collision name="hand">
        <origin xyz="0.0 0 0.025" rpy="0 1.5708 0"/>
        <geometry>
          <cylinder radius="0.025" length="0.00451872"/>
        </geometry>
      </collision>
      <collision name="hand-servo">
        <origin xyz="-0.030 0.0 0.024" rpy="0 0 0"/>
        <geometry>
          <box size="0.03 0.04 0.02"/>
        </geometry>
      </collision>
    </link>

    <link name="left_finger_base_link">
      <inertial>
        <origin xyz="0 0 0" rpy="0 0 0"/>
        <mass value="0.1"/>
        <inertia ixx="0.0001" ixy="0" ixz="0" iyy="0.0001" iyz="0" izz="0.0001"/>
      </inertial>
      <visual name="left_finger_base">
        <origin xyz="0 0 0" rpy="0 0 0"/>
        <geometry>
          <mesh filename="nuro_arm/assets/meshes/finger_base.stl" scale="0.001 0.001 0.001"/>
        </geometry>
        <material name="black"/>
      </visual>
      <collision name="left_finger_base">
        <origin xyz="0 0 0.011125001" rpy="0 0 0"/>
        <geometry>
          <box size="0.003 0.01 0.0375"/>
        </geometry>
      </collision>
    </link>

    <link name="right_finger_base_link">
      <inertial>
        <origin xyz="0 0 0" rpy="0 0 0"/>
        <mass value="0.1"/>
        <inertia ixx="0.0001" ixy="0" ixz="0" iyy="0.0001" iyz="0" izz="0.0001"/>
      </inertial>
      <visual name="right_finger_base">
        <origin xyz="0 0 0" rpy="0 0 0"/>
        <geometry>
          <mesh filename="nuro_arm/assets/meshes/finger_base.stl" scale="0.001 0.001 0.001"/>
        </geometry>
        <material name="black"/>
      </visual>
      <collision name="right-finger-lower">
        <origin xyz="0 0 0.011125001" rpy="0 0 0"/>
        <geometry>
          <box size="0.003 0.01 0.0375"/>
        </geometry>
      </collision>
    </link>

    <link name="left_finger_tip_link">
      <inertial>
        <origin xyz="0 0 0" rpy="0 0 0"/>
        <mass value="0.01"/>
        <inertia ixx="0.0001" ixy="0" ixz="0" iyy="0.0001" iyz="0" izz="0.0001"/>
      </inertial>
      <visual name="left_finger_tip">
        <origin xyz="0 0 0" rpy="0 0 0"/>
        <geometry>
          <mesh filename="nuro_arm/assets/meshes/finger_tip.stl" scale="0.001 0.001 0.001"/>
        </geometry>
        <material name="black"/>
      </visual>
      <collision name="left_finger_tip_collision">
        <origin xyz="0.0 -0.01 0.045" rpy="0 0 0"/>
        <geometry>
          <box size="0.008 0.008 0.012"/>
        </geometry>
      </collision>
	  <contact>
        <lateral_friction value="1.0"/>
        <spinning_friction value="1.0"/>
      </contact>
    </link>

    <link name="right_finger_tip_link">
      <inertial>
        <origin xyz="0 0 0" rpy="0 0 0"/>
        <mass value="0.01"/>
        <inertia ixx="0.0001" ixy="0" ixz="0" iyy="0.0001" iyz="0" izz="0.0001"/>
      </inertial>
      <visual name="right_finger_tip">
        <origin xyz="0 0.0 0.0" rpy="0 0 3.14159"/>
        <geometry>
          <mesh filename="nuro_arm/assets/meshes/finger_tip.stl" scale="0.001 0.001 0.001"/>
        </geometry>
        <material name="black"/>
      </visual>
      <collision name="right_finger_tip_collision">
        <origin xyz="0.0 0.01 0.045" rpy="0 0 0"/>
        <geometry>
          <box size="0.008 0.008 0.012"/>
        </geometry>
      </collision>
	  <contact>
        <lateral_friction value="1.0"/>
        <spinning_friction value="1.0"/>
      </contact>
    </link>

    <link name="dummy_link">
      <inertial>
        <origin xyz="0 0 0" rpy="0 0 0"/>
        <mass value="0.01"/>
        <inertia ixx="0.0001" ixy="0" ixz="0" iyy="0.0001" iyz="0" izz="0.0001"/>
      </inertial>
    </link>

    <link name="virtual_grasp_link">
        <visual>
              <origin rpy="0 0 0.0" xyz="0 0.0 0.0"/>
              <geometry>
                <sphere radius="0.003"/>
              </geometry>
              <material name="red">
                <color rgba="0.8 0.2 0.2 0.5"/>
              </material>
        </visual>
        <inertial>
            <mass value="0.001"/>
            <inertia ixx="0.00001" ixy="0" ixz="0" iyy="0.00001" iyz="0" izz="0.00001"/>
        </inertial>
    </link>

    <joint name="world_joint" type="fixed">
        <parent link="world"/>
        <child link="base_link"/>
        <origin rpy="0.0 0.0 0.0" xyz="0.0 0.0 0.0"/>
    </joint>

    <joint name="base_joint" type="revolute">
      <origin xyz="0 0 0.047" rpy="0 0 0"/>
      <parent link="base_link"/>
      <child link="swivel_link"/>
      <axis xyz="0 0 1.0"/>
      <limit lower="-2.0" upper="2.0" effort="0" velocity="2.0"/>
      <dynamics friction="0" damping="0.5"/>
    </joint>

    <joint name="shoulder_joint" type="revolute">
      <origin xyz="0 0 0.0177" rpy="0 0 0"/>
      <parent link="swivel_link"/>
      <child link="upperarm_link"/>
      <axis xyz="0 1 0"/>
      <limit lower="-1.58" upper="1.58" effort="0" velocity="2.0"/>
      <dynamics friction="0" damping="0.5"/>
    </joint>

    <joint name="elbow_joint" type="revolute">
      <origin xyz="0 0 0.0988" rpy="0 0 0"/>
      <parent link="upperarm_link"/>
      <child link="forearm_link"/>
      <axis xyz="0 1 0"/>
      <limit lower="-2.0" upper="2.0" velocity="2.0"/>
      <dynamics friction="0" damping="0.5"/>
    </joint>

    <joint name="wrist_joint" type="revolute">
      <origin xyz="0 0 0.0947" rpy="0 0 0"/>
      <parent link="forearm_link"/>
      <child link="wrist_link"/>
      <axis xyz="0 1 0"/>
      <limit lower="-1.8" upper="2.0" velocity="2.0"/>
      <dynamics friction="0" damping="0.5"/>
    </joint>

    <joint name="wrist_rotation_joint" type="revolute">
      <origin xyz="0 0 0.0588" rpy="0 0 0"/>
      <parent link="wrist_link"/>
      <child link="hand_link"/>
      <axis xyz="0 0 1"/>
      <limit lower="-2.0" upper="2.0" velocity="2.0"/>
      <dynamics friction="0" damping="0.5"/>
    </joint>

    <joint name="left_knuckle_joint" type="revolute">
        <origin xyz="0 0.014 0.025" rpy="0 0 0"/>
      <parent link="hand_link"/>
      <child link="left_finger_base_link"/>
      <axis xyz="-1 0 0"/>
      <limit effort="1000" lower="0.05" upper="1.6" velocity="2.0"/>
      <dynamics friction="0" damping="0.5"/>
    </joint>

    <joint name="right_knuckle_joint" type="revolute">
      <origin xyz="0 -0.014 0.025" rpy="0 0 0"/>
      <parent link="hand_link"/>
      <child link="right_finger_base_link"/>
      <axis xyz="1 0 0"/>
      <limit effort="1000" lower="0.05" upper="1.6" velocity="2.0"/>
      <dynamics friction="0" damping="0.5"/>
    </joint>

    <joint name="dummy_z_joint" type="prismatic">
        <parent link="hand_link"/>
        <child link="dummy_link"/>
        <origin rpy="0.0 0.0 0.0" xyz="0.0 0.0 0.0"/>
        <axis xyz="0 0 1"/>
        <limit effort="1000" lower="0.025" upper="0.055" velocity="2.0"/>
    </joint>

    <joint name="dummy_y_joint" type="prismatic">
        <parent link="dummy_link"/>
        <child link="left_finger_tip_link"/>
        <origin rpy="0.0 0.0 0.0" xyz="0.0 0.0 0.0"/>
        <axis xyz="0 1 0"/>
        <limit effort="1000" lower="0.0145" upper="0.0445" velocity="2.0"/>
    </joint>

    <joint name="finger_separation_joint" type="prismatic">
        <parent link="left_finger_tip_link"/>
        <child link="right_finger_tip_link"/>
        <origin rpy="0.0 0.0 0.0" xyz="0.0 0.00 0.0"/>
        <axis xyz="0 -1 0"/>
        <limit effort="1000" lower="0.029" upper="0.089" velocity="2.0"/>
    </joint>

    <joint name="virtual_grasp_joint" type="fixed">
        <parent link="hand_link"/>
        <child link="virtual_grasp_link"/>
        <origin rpy="0.0 0.0 0.0" xyz="0.0 0.0 0.1"/>
    </joint>

    <material name="black">
      <color rgba="0.2 0.2 0.2 0.9"/>
    </material>

    <material name="blue">
      <color rgba="0.5 0.5 0.5 1.0"/>
    </material>

    <material name="pink">
        <color rgba="0.8 0.3 0.6 1.0"/>
    </material>
  </robot>
