<?xml version="1.0" ?>
<robot name="Camera">

 	<link name="world"/>

	<link name="base_link">
		<visual>
			<origin rpy="0 0 0.0" xyz="0 0 0"/>
      		<geometry>
                <mesh filename="src/assets/meshes/base_rod_holder.dae"/>
      		</geometry>
		</visual>
		<visual>
			<origin rpy="0 0 0.0" xyz="0 0 0.1524"/>
      		<geometry>
                <cylinder radius="0.0047625" length="0.3048" />
      		</geometry>
            <material name="gray">
                <color rgba="0.4 0.4 0.4 1.0"/>
            </material>
		</visual>
        <collision>
            <origin rpy="0 0 0.0" xyz="0 -0.01 0.0075"/>
            <geometry>
              <box size="0.06 0.06 0.015"/>
            </geometry>
        </collision>
        <collision>
            <origin rpy="0 0 0.0" xyz="0 0 0.1524"/>
              <geometry>
                <cylinder radius="0.0047625" length="0.3048" />
              </geometry>
        </collision>
        <inertial>
            <mass value="1"/>
            <inertia ixx="0.0001" ixy="0" ixz="0" iyy="0.0001" iyz="0" izz="0.00001"/>
        </inertial>
  	</link>

	<link name="dummy_holder_link">
        <inertial>
            <mass value="1"/>
            <inertia ixx="0.0001" ixy="0" ixz="0" iyy="0.0001" iyz="0" izz="0.00001"/>
        </inertial>
  	</link>

    <link name="holder_link">
        <visual>
              <origin rpy="0 0 0" xyz="0.0 0.0 0.0"/>
              <geometry>
                <mesh filename="src/assets/meshes/top_rod_holder.dae"/>
              </geometry>
              <material name="gray">
                <color rgba="0.4 0.4 0.4 1.0"/>
              </material>
        </visual>
        <collision>
              <origin rpy="0 0 0" xyz="0.0 -0.005 0.0"/>
              <geometry>
                  <box size="0.02 0.05 0.012"/>
              </geometry>
        </collision>
        <inertial>
            <mass value="1"/>
            <inertia ixx="0.0001" ixy="0" ixz="0" iyy="0.0001" iyz="0" izz="0.00001"/>
        </inertial>
    </link>

    <link name="camera_link">
        <visual>
              <origin rpy="0 0 0" xyz="0.0 0.0 0.0"/>
              <geometry>
                  <mesh filename="src/assets/meshes/camera_with_holder.dae"/>
              </geometry>
              <material name="gray">
                <color rgba="0.4 0.4 0.4 1.0"/>
              </material>
        </visual>
        <collision>
              <origin rpy="0 0 0" xyz="0.0 0.0 -0.01"/>
              <geometry>
                  <box size="0.04 0.03 0.04"/>
              </geometry>
        </collision>
        <inertial>
            <mass value="1"/>
            <inertia ixx="0.0001" ixy="0" ixz="0" iyy="0.0001" iyz="0" izz="0.00001"/>
        </inertial>
    </link>

    <joint name="world_joint" type="fixed">
        <parent link="world"/>
        <child link="camera_link"/>
        <origin rpy="0.0 0.0 0.0" xyz="0.0 0.0 0.0"/>
    </joint>

    <joint name="pitch" type="revolute">
        <parent link="camera_link"/>
        <child link="holder_link"/>
        <origin rpy="0.0 0.0 0.0" xyz="0.0 0.027 0.0"/>
        <limit lower="0" upper="6.28319" velocity="1"/>
        <axis xyz="0 0 1"/>
    </joint>

     <joint name="yaw" type="revolute">
        <parent link="holder_link"/>
        <child link="dummy_holder_link"/>
        <origin rpy="0.0 0.0 0.0" xyz="0.0 0.0 0.0"/>
        <limit lower="0" upper="6.28319" velocity="1"/>
        <axis xyz="0 0 1"/>
      </joint>

      <joint name="height" type="prismatic">
        <parent link="dummy_holder_link"/>
        <child link="base_link"/>
        <origin rpy="0.0 0.0 0.0" xyz="0.0 0.0 0.0"/>
        <limit lower="0.03" upper="0.3" velocity="1"/>
        <axis xyz="0 0 -1"/>
      </joint>
</robot>
