<?xml version="1.0" ?>
<robot name="Camera">

 	<link name="world"/>

	<link name="base_link">
		<visual>
			<origin rpy="0 0 0.0" xyz="0 0 0"/>
      		<geometry>
                <mesh filename="src/assets/meshes/base_rod_holder.stl"/>
      		</geometry>
		</visual>
		<visual>
			<origin rpy="0 0 0.0" xyz="0 0 0.1524"/>
      		<geometry>
                <cylinder radius="0.0047625" length="0.3048" />
      		</geometry>
            <material name="gray">
                <color rgba="0.4 0.4 0.4 1.0"/>
            </material>
		</visual>
		<collision>
			<origin rpy="0 0 0.0" xyz="0 0 0"/>
      		<geometry>
                <mesh filename="src/assets/meshes/base_rod_holder.stl"/>
      		</geometry>
		</collision>
		<collision>
			<origin rpy="0 0 0.0" xyz="0 0 0.1524"/>
      		<geometry>
                <cylinder radius="0.0047625" length="0.3048" />
      		</geometry>
		</collision>
        <inertial>
            <mass value="1"/>
            <inertia ixx="0.0001" ixy="0" ixz="0" iyy="0.0001" iyz="0" izz="0.00001"/>
        </inertial>
  	</link>

      <link name="holder_link">
        <visual>
              <origin rpy="0 0 0" xyz="0.0 0.0 0.0"/>
              <geometry>
                <mesh filename="src/assets/meshes/top_rod_holder.stl"/>
              </geometry>
              <material name="gray">
                <color rgba="0.4 0.4 0.4 1.0"/>
              </material>
        </visual>
        <collision>
              <origin rpy="0 0 0" xyz="0.0 0.0 0.0"/>
              <geometry>
                <mesh filename="src/assets/meshes/top_rod_holder.stl"/>
              </geometry>
        </collision>
        <inertial>
            <mass value="1"/>
            <inertia ixx="0.0001" ixy="0" ixz="0" iyy="0.0001" iyz="0" izz="0.00001"/>
        </inertial>
      </link>

      <link name="camera_link">
        <visual>
              <origin rpy="0 0 0" xyz="0.0 0.0 0.0"/>
              <geometry>
                  <mesh filename="src/assets/meshes/camera_with_holder.stl"/>
              </geometry>
              <material name="gray">
                <color rgba="0.4 0.4 0.4 1.0"/>
              </material>
        </visual>
		<collision>
              <origin rpy="0 0 0" xyz="0.0 0.0 0.0"/>
              <geometry>
                  <mesh filename="src/assets/meshes/camera_with_holder.stl"/>
              </geometry>
		</collision>
        <inertial>
            <mass value="1"/>
            <inertia ixx="0.0001" ixy="0" ixz="0" iyy="0.0001" iyz="0" izz="0.00001"/>
        </inertial>
      </link>

     <joint name="world_joint" type="fixed">
        <parent link="world"/>
        <child link="base_link"/>
        <origin rpy="0.0 0.0 0.0" xyz="0.0 0.0 0.0"/>
     </joint>

      <joint name="yaw_joint" type="revolute">
        <parent link="base_link"/>
        <child link="holder_link"/>
        <origin rpy="0.0 0.0 0.0" xyz="0.0 0.0 0.0"/>
        <limit lower="0" upper="6.28319" velocity="1"/>
        <axis xyz="0 0 1"/>
      </joint>

      <joint name="pitch_joint" type="revolute">
        <parent link="holder_link"/>
        <child link="camera_link"/>
        <origin rpy="0.0 0.0 0.0" xyz="0.0 0.0 0.0"/>
        <limit lower="0" upper="6.28319" velocity="1"/>
        <axis xyz="1 0 0"/>
      </joint>
</robot>
